[2024-12-11T16:01:27.919+0000] {local_task_job_runner.py:120} INFO - ::group::Pre task execution logs
[2024-12-11T16:01:27.949+0000] {taskinstance.py:2076} INFO - Dependencies all met for dep_context=non-requeueable deps ti=<TaskInstance: dbt_orchestrator.dbt_connection_check.dbt_debug scheduled__2024-12-11T15:45:00+00:00 [queued]>
[2024-12-11T16:01:27.958+0000] {taskinstance.py:2076} INFO - Dependencies all met for dep_context=requeueable deps ti=<TaskInstance: dbt_orchestrator.dbt_connection_check.dbt_debug scheduled__2024-12-11T15:45:00+00:00 [queued]>
[2024-12-11T16:01:27.958+0000] {taskinstance.py:2306} INFO - Starting attempt 2 of 2
[2024-12-11T16:01:27.973+0000] {taskinstance.py:2330} INFO - Executing <Task(BashOperator): dbt_connection_check.dbt_debug> on 2024-12-11 15:45:00+00:00
[2024-12-11T16:01:27.979+0000] {standard_task_runner.py:63} INFO - Started process 68 to run task
[2024-12-11T16:01:27.981+0000] {standard_task_runner.py:90} INFO - Running: ['***', 'tasks', 'run', 'dbt_orchestrator', 'dbt_connection_check.dbt_debug', 'scheduled__2024-12-11T15:45:00+00:00', '--job-id', '18', '--raw', '--subdir', 'DAGS_FOLDER/pipeline.py', '--cfg-path', '/tmp/tmp04lujrb7']
[2024-12-11T16:01:27.982+0000] {standard_task_runner.py:91} INFO - Job 18: Subtask dbt_connection_check.dbt_debug
[2024-12-11T16:01:28.027+0000] {task_command.py:426} INFO - Running <TaskInstance: dbt_orchestrator.dbt_connection_check.dbt_debug scheduled__2024-12-11T15:45:00+00:00 [running]> on host 49f8df2c9427
[2024-12-11T16:01:28.107+0000] {taskinstance.py:2648} INFO - Exporting env vars: AIRFLOW_CTX_DAG_OWNER='Mahmoud' AIRFLOW_CTX_DAG_ID='dbt_orchestrator' AIRFLOW_CTX_TASK_ID='dbt_connection_check.dbt_debug' AIRFLOW_CTX_EXECUTION_DATE='2024-12-11T15:45:00+00:00' AIRFLOW_CTX_TRY_NUMBER='2' AIRFLOW_CTX_DAG_RUN_ID='scheduled__2024-12-11T15:45:00+00:00'
[2024-12-11T16:01:28.108+0000] {taskinstance.py:430} INFO - ::endgroup::
[2024-12-11T16:01:28.119+0000] {subprocess.py:63} INFO - Tmp dir root location: /tmp
[2024-12-11T16:01:28.120+0000] {subprocess.py:75} INFO - Running command: ['/usr/bin/bash', '-c', 'dbt debug --profiles-dir /opt/***/dbt --project-dir /opt/***/dbt/ecommerce']
[2024-12-11T16:01:28.131+0000] {subprocess.py:86} INFO - Output:
[2024-12-11T16:01:29.907+0000] {subprocess.py:93} INFO - [0m16:01:29  Running with dbt=1.8.0
[2024-12-11T16:01:29.916+0000] {subprocess.py:93} INFO - [0m16:01:29  dbt version: 1.8.0
[2024-12-11T16:01:29.917+0000] {subprocess.py:93} INFO - [0m16:01:29  python version: 3.9.19
[2024-12-11T16:01:29.917+0000] {subprocess.py:93} INFO - [0m16:01:29  python path: /home/***/.local/bin/python
[2024-12-11T16:01:29.918+0000] {subprocess.py:93} INFO - [0m16:01:29  os info: Linux-6.8.0-49-generic-x86_64-with-glibc2.36
[2024-12-11T16:01:29.991+0000] {subprocess.py:93} INFO - [0m16:01:29  Using profiles dir at /opt/***/dbt
[2024-12-11T16:01:29.991+0000] {subprocess.py:93} INFO - [0m16:01:29  Using profiles.yml file at /opt/***/dbt/profiles.yml
[2024-12-11T16:01:29.992+0000] {subprocess.py:93} INFO - [0m16:01:29  Using dbt_project.yml file at /opt/***/dbt/ecommerce/dbt_project.yml
[2024-12-11T16:01:29.993+0000] {subprocess.py:93} INFO - [0m16:01:29  adapter type: postgres
[2024-12-11T16:01:29.994+0000] {subprocess.py:93} INFO - [0m16:01:29  adapter version: 1.8.0
[2024-12-11T16:01:30.073+0000] {subprocess.py:93} INFO - [0m16:01:30  [[33mWARNING[0m]: Deprecated functionality
[2024-12-11T16:01:30.073+0000] {subprocess.py:93} INFO - The `tests` config has been renamed to `data_tests`. Please see
[2024-12-11T16:01:30.073+0000] {subprocess.py:93} INFO - https://docs.getdbt.com/docs/build/data-tests#new-data_tests-syntax for more
[2024-12-11T16:01:30.073+0000] {subprocess.py:93} INFO - information.
[2024-12-11T16:01:30.116+0000] {subprocess.py:93} INFO - [0m16:01:30  Configuration:
[2024-12-11T16:01:30.117+0000] {subprocess.py:93} INFO - [0m16:01:30    profiles.yml file [[32mOK found and valid[0m]
[2024-12-11T16:01:30.118+0000] {subprocess.py:93} INFO - [0m16:01:30    dbt_project.yml file [[32mOK found and valid[0m]
[2024-12-11T16:01:30.118+0000] {subprocess.py:93} INFO - [0m16:01:30  Required dependencies:
[2024-12-11T16:01:30.128+0000] {subprocess.py:93} INFO - [0m16:01:30   - git [[32mOK found[0m]
[2024-12-11T16:01:30.129+0000] {subprocess.py:93} INFO - 
[2024-12-11T16:01:30.129+0000] {subprocess.py:93} INFO - [0m16:01:30  Connection:
[2024-12-11T16:01:30.129+0000] {subprocess.py:93} INFO - [0m16:01:30    host: 172.18.0.3
[2024-12-11T16:01:30.130+0000] {subprocess.py:93} INFO - [0m16:01:30    port: 5432
[2024-12-11T16:01:30.130+0000] {subprocess.py:93} INFO - [0m16:01:30    user: pgdb
[2024-12-11T16:01:30.131+0000] {subprocess.py:93} INFO - [0m16:01:30    database: ecommerce
[2024-12-11T16:01:30.131+0000] {subprocess.py:93} INFO - [0m16:01:30    schema: oltp
[2024-12-11T16:01:30.132+0000] {subprocess.py:93} INFO - [0m16:01:30    connect_timeout: 10
[2024-12-11T16:01:30.132+0000] {subprocess.py:93} INFO - [0m16:01:30    role: None
[2024-12-11T16:01:30.133+0000] {subprocess.py:93} INFO - [0m16:01:30    search_path: None
[2024-12-11T16:01:30.133+0000] {subprocess.py:93} INFO - [0m16:01:30    keepalives_idle: 0
[2024-12-11T16:01:30.134+0000] {subprocess.py:93} INFO - [0m16:01:30    sslmode: None
[2024-12-11T16:01:30.134+0000] {subprocess.py:93} INFO - [0m16:01:30    sslcert: None
[2024-12-11T16:01:30.135+0000] {subprocess.py:93} INFO - [0m16:01:30    sslkey: None
[2024-12-11T16:01:30.135+0000] {subprocess.py:93} INFO - [0m16:01:30    sslrootcert: None
[2024-12-11T16:01:30.136+0000] {subprocess.py:93} INFO - [0m16:01:30    application_name: dbt
[2024-12-11T16:01:30.137+0000] {subprocess.py:93} INFO - [0m16:01:30    retries: 1
[2024-12-11T16:01:30.137+0000] {subprocess.py:93} INFO - [0m16:01:30  Registered adapter: postgres=1.8.0
[2024-12-11T16:01:30.293+0000] {subprocess.py:93} INFO - [0m16:01:30    Connection test: [[31mERROR[0m]
[2024-12-11T16:01:30.294+0000] {subprocess.py:93} INFO - 
[2024-12-11T16:01:30.294+0000] {subprocess.py:93} INFO - [0m16:01:30  [31m1 check failed:[0m
[2024-12-11T16:01:30.294+0000] {subprocess.py:93} INFO - [0m16:01:30  dbt was unable to connect to the specified database.
[2024-12-11T16:01:30.295+0000] {subprocess.py:93} INFO - The database returned the following error:
[2024-12-11T16:01:30.295+0000] {subprocess.py:93} INFO - 
[2024-12-11T16:01:30.295+0000] {subprocess.py:93} INFO -   >Database Error
[2024-12-11T16:01:30.296+0000] {subprocess.py:93} INFO -   connection to server at "172.18.0.3", port 5432 failed: FATAL:  password authentication failed for user "pgdb"
[2024-12-11T16:01:30.296+0000] {subprocess.py:93} INFO - 
[2024-12-11T16:01:30.296+0000] {subprocess.py:93} INFO - 
[2024-12-11T16:01:30.296+0000] {subprocess.py:93} INFO - Check your database credentials and try again. For more information, visit:
[2024-12-11T16:01:30.296+0000] {subprocess.py:93} INFO - https://docs.getdbt.com/docs/configure-your-profile
[2024-12-11T16:01:30.297+0000] {subprocess.py:93} INFO - 
[2024-12-11T16:01:30.297+0000] {subprocess.py:93} INFO - 
[2024-12-11T16:01:31.415+0000] {subprocess.py:97} INFO - Command exited with return code 1
[2024-12-11T16:01:31.416+0000] {taskinstance.py:441} INFO - ::group::Post task execution logs
[2024-12-11T16:01:31.426+0000] {taskinstance.py:2905} ERROR - Task failed with exception
Traceback (most recent call last):
  File "/home/airflow/.local/lib/python3.9/site-packages/airflow/models/taskinstance.py", line 465, in _execute_task
    result = _execute_callable(context=context, **execute_callable_kwargs)
  File "/home/airflow/.local/lib/python3.9/site-packages/airflow/models/taskinstance.py", line 432, in _execute_callable
    return execute_callable(context=context, **execute_callable_kwargs)
  File "/home/airflow/.local/lib/python3.9/site-packages/airflow/models/baseoperator.py", line 400, in wrapper
    return func(self, *args, **kwargs)
  File "/home/airflow/.local/lib/python3.9/site-packages/airflow/operators/bash.py", line 243, in execute
    raise AirflowException(
airflow.exceptions.AirflowException: Bash command failed. The command returned a non-zero exit code 1.
[2024-12-11T16:01:31.429+0000] {taskinstance.py:1206} INFO - Marking task as FAILED. dag_id=dbt_orchestrator, task_id=dbt_connection_check.dbt_debug, run_id=scheduled__2024-12-11T15:45:00+00:00, execution_date=20241211T154500, start_date=20241211T160127, end_date=20241211T160131
[2024-12-11T16:01:31.441+0000] {standard_task_runner.py:110} ERROR - Failed to execute job 18 for task dbt_connection_check.dbt_debug (Bash command failed. The command returned a non-zero exit code 1.; 68)
[2024-12-11T16:01:31.483+0000] {local_task_job_runner.py:240} INFO - Task exited with return code 1
[2024-12-11T16:01:31.506+0000] {taskinstance.py:3498} INFO - 0 downstream tasks scheduled from follow-on schedule check
[2024-12-11T16:01:31.508+0000] {local_task_job_runner.py:222} INFO - ::endgroup::
