[2024-12-12T08:50:24.154+0000] {local_task_job_runner.py:120} INFO - ::group::Pre task execution logs
[2024-12-12T08:50:24.181+0000] {taskinstance.py:2076} INFO - Dependencies all met for dep_context=non-requeueable deps ti=<TaskInstance: dbt_orchestrator.dbt_run_fact.dbt_run_fact_model_fact_sales scheduled__2024-12-12T08:00:00+00:00 [queued]>
[2024-12-12T08:50:24.197+0000] {taskinstance.py:2076} INFO - Dependencies all met for dep_context=requeueable deps ti=<TaskInstance: dbt_orchestrator.dbt_run_fact.dbt_run_fact_model_fact_sales scheduled__2024-12-12T08:00:00+00:00 [queued]>
[2024-12-12T08:50:24.198+0000] {taskinstance.py:2306} INFO - Starting attempt 7 of 7
[2024-12-12T08:50:24.215+0000] {taskinstance.py:2330} INFO - Executing <Task(BashOperator): dbt_run_fact.dbt_run_fact_model_fact_sales> on 2024-12-12 08:00:00+00:00
[2024-12-12T08:50:24.223+0000] {standard_task_runner.py:63} INFO - Started process 1514 to run task
[2024-12-12T08:50:24.226+0000] {standard_task_runner.py:90} INFO - Running: ['***', 'tasks', 'run', 'dbt_orchestrator', 'dbt_run_fact.dbt_run_fact_model_fact_sales', 'scheduled__2024-12-12T08:00:00+00:00', '--job-id', '315', '--raw', '--subdir', 'DAGS_FOLDER/pipeline.py', '--cfg-path', '/tmp/tmp_6hpw3ww']
[2024-12-12T08:50:24.227+0000] {standard_task_runner.py:91} INFO - Job 315: Subtask dbt_run_fact.dbt_run_fact_model_fact_sales
[2024-12-12T08:50:24.274+0000] {task_command.py:426} INFO - Running <TaskInstance: dbt_orchestrator.dbt_run_fact.dbt_run_fact_model_fact_sales scheduled__2024-12-12T08:00:00+00:00 [running]> on host 34fdc836a0bb
[2024-12-12T08:50:24.368+0000] {taskinstance.py:2648} INFO - Exporting env vars: AIRFLOW_CTX_DAG_OWNER='ma7moud' AIRFLOW_CTX_DAG_ID='dbt_orchestrator' AIRFLOW_CTX_TASK_ID='dbt_run_fact.dbt_run_fact_model_fact_sales' AIRFLOW_CTX_EXECUTION_DATE='2024-12-12T08:00:00+00:00' AIRFLOW_CTX_TRY_NUMBER='7' AIRFLOW_CTX_DAG_RUN_ID='scheduled__2024-12-12T08:00:00+00:00'
[2024-12-12T08:50:24.369+0000] {taskinstance.py:430} INFO - ::endgroup::
[2024-12-12T08:50:24.380+0000] {subprocess.py:63} INFO - Tmp dir root location: /tmp
[2024-12-12T08:50:24.381+0000] {subprocess.py:75} INFO - Running command: ['/usr/bin/bash', '-c', 'dbt run --profiles-dir /opt/***/dbt --project-dir /opt/***/dbt/ecommerce --models fact_sales']
[2024-12-12T08:50:24.396+0000] {subprocess.py:86} INFO - Output:
[2024-12-12T08:50:26.416+0000] {subprocess.py:93} INFO - [0m08:50:26  Running with dbt=1.8.0
[2024-12-12T08:50:26.570+0000] {subprocess.py:93} INFO - [0m08:50:26  [[33mWARNING[0m]: Deprecated functionality
[2024-12-12T08:50:26.571+0000] {subprocess.py:93} INFO - The `tests` config has been renamed to `data_tests`. Please see
[2024-12-12T08:50:26.571+0000] {subprocess.py:93} INFO - https://docs.getdbt.com/docs/build/data-tests#new-data_tests-syntax for more
[2024-12-12T08:50:26.571+0000] {subprocess.py:93} INFO - information.
[2024-12-12T08:50:26.733+0000] {subprocess.py:93} INFO - [0m08:50:26  Registered adapter: postgres=1.8.0
[2024-12-12T08:50:27.519+0000] {subprocess.py:93} INFO - [0m08:50:27  Found 15 models, 1 snapshot, 112 data tests, 12 sources, 430 macros
[2024-12-12T08:50:27.523+0000] {subprocess.py:93} INFO - [0m08:50:27
[2024-12-12T08:50:27.787+0000] {subprocess.py:93} INFO - [0m08:50:27  Concurrency: 3 threads (target='dev')
[2024-12-12T08:50:27.787+0000] {subprocess.py:93} INFO - [0m08:50:27
[2024-12-12T08:50:27.791+0000] {subprocess.py:93} INFO - [0m08:50:27  1 of 1 START sql incremental model oltp_fact.fact_sales ........................ [RUN]
[2024-12-12T08:50:27.913+0000] {subprocess.py:93} INFO - [0m08:50:27  1 of 1 ERROR creating sql incremental model oltp_fact.fact_sales ............... [[31mERROR[0m in 0.12s]
[2024-12-12T08:50:27.942+0000] {subprocess.py:93} INFO - [0m08:50:27
[2024-12-12T08:50:27.943+0000] {subprocess.py:93} INFO - [0m08:50:27  Finished running 1 incremental model in 0 hours 0 minutes and 0.42 seconds (0.42s).
[2024-12-12T08:50:28.032+0000] {subprocess.py:93} INFO - [0m08:50:28
[2024-12-12T08:50:28.033+0000] {subprocess.py:93} INFO - [0m08:50:28  [31mCompleted with 1 error and 0 warnings:[0m
[2024-12-12T08:50:28.033+0000] {subprocess.py:93} INFO - [0m08:50:28
[2024-12-12T08:50:28.034+0000] {subprocess.py:93} INFO - [0m08:50:28    Database Error in model fact_sales (models/olap_model/fact/fact_sales.sql)
[2024-12-12T08:50:28.034+0000] {subprocess.py:93} INFO -   relation "oltp_dimensions.data_dim" does not exist
[2024-12-12T08:50:28.034+0000] {subprocess.py:93} INFO -   LINE 56:     left join "ecommerce"."oltp_dimensions"."data_dim" d
[2024-12-12T08:50:28.035+0000] {subprocess.py:93} INFO -                          ^
[2024-12-12T08:50:28.035+0000] {subprocess.py:93} INFO -   compiled code at target/run/ecommerce/models/olap_model/fact/fact_sales.sql
[2024-12-12T08:50:28.035+0000] {subprocess.py:93} INFO - [0m08:50:28
[2024-12-12T08:50:28.035+0000] {subprocess.py:93} INFO - [0m08:50:28  Done. PASS=0 WARN=0 ERROR=1 SKIP=0 TOTAL=1
[2024-12-12T08:50:29.016+0000] {subprocess.py:97} INFO - Command exited with return code 1
[2024-12-12T08:50:29.017+0000] {taskinstance.py:441} INFO - ::group::Post task execution logs
[2024-12-12T08:50:29.031+0000] {taskinstance.py:2905} ERROR - Task failed with exception
Traceback (most recent call last):
  File "/home/airflow/.local/lib/python3.9/site-packages/airflow/models/taskinstance.py", line 465, in _execute_task
    result = _execute_callable(context=context, **execute_callable_kwargs)
  File "/home/airflow/.local/lib/python3.9/site-packages/airflow/models/taskinstance.py", line 432, in _execute_callable
    return execute_callable(context=context, **execute_callable_kwargs)
  File "/home/airflow/.local/lib/python3.9/site-packages/airflow/models/baseoperator.py", line 400, in wrapper
    return func(self, *args, **kwargs)
  File "/home/airflow/.local/lib/python3.9/site-packages/airflow/operators/bash.py", line 243, in execute
    raise AirflowException(
airflow.exceptions.AirflowException: Bash command failed. The command returned a non-zero exit code 1.
[2024-12-12T08:50:29.037+0000] {taskinstance.py:1206} INFO - Marking task as FAILED. dag_id=dbt_orchestrator, task_id=dbt_run_fact.dbt_run_fact_model_fact_sales, run_id=scheduled__2024-12-12T08:00:00+00:00, execution_date=20241212T080000, start_date=20241212T085024, end_date=20241212T085029
[2024-12-12T08:50:29.055+0000] {standard_task_runner.py:110} ERROR - Failed to execute job 315 for task dbt_run_fact.dbt_run_fact_model_fact_sales (Bash command failed. The command returned a non-zero exit code 1.; 1514)
[2024-12-12T08:50:29.092+0000] {local_task_job_runner.py:240} INFO - Task exited with return code 1
[2024-12-12T08:50:29.121+0000] {taskinstance.py:3498} INFO - 0 downstream tasks scheduled from follow-on schedule check
[2024-12-12T08:50:29.125+0000] {local_task_job_runner.py:222} INFO - ::endgroup::
