[2024-12-11T15:57:28.620+0000] {local_task_job_runner.py:120} INFO - ::group::Pre task execution logs
[2024-12-11T15:57:28.648+0000] {taskinstance.py:2076} INFO - Dependencies all met for dep_context=non-requeueable deps ti=<TaskInstance: dbt_orchestrator.dbt_connection_check.dbt_debug scheduled__2024-12-11T15:30:00+00:00 [queued]>
[2024-12-11T15:57:28.657+0000] {taskinstance.py:2076} INFO - Dependencies all met for dep_context=requeueable deps ti=<TaskInstance: dbt_orchestrator.dbt_connection_check.dbt_debug scheduled__2024-12-11T15:30:00+00:00 [queued]>
[2024-12-11T15:57:28.658+0000] {taskinstance.py:2306} INFO - Starting attempt 5 of 5
[2024-12-11T15:57:28.669+0000] {taskinstance.py:2330} INFO - Executing <Task(BashOperator): dbt_connection_check.dbt_debug> on 2024-12-11 15:30:00+00:00
[2024-12-11T15:57:28.674+0000] {standard_task_runner.py:63} INFO - Started process 50 to run task
[2024-12-11T15:57:28.677+0000] {standard_task_runner.py:90} INFO - Running: ['***', 'tasks', 'run', 'dbt_orchestrator', 'dbt_connection_check.dbt_debug', 'scheduled__2024-12-11T15:30:00+00:00', '--job-id', '15', '--raw', '--subdir', 'DAGS_FOLDER/pipeline.py', '--cfg-path', '/tmp/tmp3m9zepny']
[2024-12-11T15:57:28.678+0000] {standard_task_runner.py:91} INFO - Job 15: Subtask dbt_connection_check.dbt_debug
[2024-12-11T15:57:28.725+0000] {task_command.py:426} INFO - Running <TaskInstance: dbt_orchestrator.dbt_connection_check.dbt_debug scheduled__2024-12-11T15:30:00+00:00 [running]> on host 49f8df2c9427
[2024-12-11T15:57:28.804+0000] {taskinstance.py:2648} INFO - Exporting env vars: AIRFLOW_CTX_DAG_OWNER='Mahmoud' AIRFLOW_CTX_DAG_ID='dbt_orchestrator' AIRFLOW_CTX_TASK_ID='dbt_connection_check.dbt_debug' AIRFLOW_CTX_EXECUTION_DATE='2024-12-11T15:30:00+00:00' AIRFLOW_CTX_TRY_NUMBER='5' AIRFLOW_CTX_DAG_RUN_ID='scheduled__2024-12-11T15:30:00+00:00'
[2024-12-11T15:57:28.805+0000] {taskinstance.py:430} INFO - ::endgroup::
[2024-12-11T15:57:28.830+0000] {subprocess.py:63} INFO - Tmp dir root location: /tmp
[2024-12-11T15:57:28.831+0000] {subprocess.py:75} INFO - Running command: ['/usr/bin/bash', '-c', 'dbt debug --profiles-dir /opt/***/dbt --project-dir /opt/***/dbt/ecommerce']
[2024-12-11T15:57:28.841+0000] {subprocess.py:86} INFO - Output:
[2024-12-11T15:57:30.954+0000] {subprocess.py:93} INFO - [0m15:57:30  Running with dbt=1.8.0
[2024-12-11T15:57:30.986+0000] {subprocess.py:93} INFO - [0m15:57:30  dbt version: 1.8.0
[2024-12-11T15:57:30.987+0000] {subprocess.py:93} INFO - [0m15:57:30  python version: 3.9.19
[2024-12-11T15:57:30.987+0000] {subprocess.py:93} INFO - [0m15:57:30  python path: /home/***/.local/bin/python
[2024-12-11T15:57:30.988+0000] {subprocess.py:93} INFO - [0m15:57:30  os info: Linux-6.8.0-49-generic-x86_64-with-glibc2.36
[2024-12-11T15:57:31.052+0000] {subprocess.py:93} INFO - [0m15:57:31  Using profiles dir at /opt/***/dbt
[2024-12-11T15:57:31.053+0000] {subprocess.py:93} INFO - [0m15:57:31  Using profiles.yml file at /opt/***/dbt/profiles.yml
[2024-12-11T15:57:31.054+0000] {subprocess.py:93} INFO - [0m15:57:31  Using dbt_project.yml file at /opt/***/dbt/ecommerce/dbt_project.yml
[2024-12-11T15:57:31.054+0000] {subprocess.py:93} INFO - [0m15:57:31  adapter type: postgres
[2024-12-11T15:57:31.055+0000] {subprocess.py:93} INFO - [0m15:57:31  adapter version: 1.8.0
[2024-12-11T15:57:31.131+0000] {subprocess.py:93} INFO - [0m15:57:31  [[33mWARNING[0m]: Deprecated functionality
[2024-12-11T15:57:31.131+0000] {subprocess.py:93} INFO - The `tests` config has been renamed to `data_tests`. Please see
[2024-12-11T15:57:31.132+0000] {subprocess.py:93} INFO - https://docs.getdbt.com/docs/build/data-tests#new-data_tests-syntax for more
[2024-12-11T15:57:31.132+0000] {subprocess.py:93} INFO - information.
[2024-12-11T15:57:31.177+0000] {subprocess.py:93} INFO - [0m15:57:31  Configuration:
[2024-12-11T15:57:31.177+0000] {subprocess.py:93} INFO - [0m15:57:31    profiles.yml file [[32mOK found and valid[0m]
[2024-12-11T15:57:31.178+0000] {subprocess.py:93} INFO - [0m15:57:31    dbt_project.yml file [[32mOK found and valid[0m]
[2024-12-11T15:57:31.179+0000] {subprocess.py:93} INFO - [0m15:57:31  Required dependencies:
[2024-12-11T15:57:31.187+0000] {subprocess.py:93} INFO - [0m15:57:31   - git [[32mOK found[0m]
[2024-12-11T15:57:31.188+0000] {subprocess.py:93} INFO - 
[2024-12-11T15:57:31.188+0000] {subprocess.py:93} INFO - [0m15:57:31  Connection:
[2024-12-11T15:57:31.189+0000] {subprocess.py:93} INFO - [0m15:57:31    host: 172.19.0.2
[2024-12-11T15:57:31.189+0000] {subprocess.py:93} INFO - [0m15:57:31    port: 5432
[2024-12-11T15:57:31.190+0000] {subprocess.py:93} INFO - [0m15:57:31    user: pgdb
[2024-12-11T15:57:31.191+0000] {subprocess.py:93} INFO - [0m15:57:31    database: ecommerce
[2024-12-11T15:57:31.191+0000] {subprocess.py:93} INFO - [0m15:57:31    schema: oltp
[2024-12-11T15:57:31.192+0000] {subprocess.py:93} INFO - [0m15:57:31    connect_timeout: 10
[2024-12-11T15:57:31.192+0000] {subprocess.py:93} INFO - [0m15:57:31    role: None
[2024-12-11T15:57:31.193+0000] {subprocess.py:93} INFO - [0m15:57:31    search_path: None
[2024-12-11T15:57:31.194+0000] {subprocess.py:93} INFO - [0m15:57:31    keepalives_idle: 0
[2024-12-11T15:57:31.194+0000] {subprocess.py:93} INFO - [0m15:57:31    sslmode: None
[2024-12-11T15:57:31.195+0000] {subprocess.py:93} INFO - [0m15:57:31    sslcert: None
[2024-12-11T15:57:31.195+0000] {subprocess.py:93} INFO - [0m15:57:31    sslkey: None
[2024-12-11T15:57:31.196+0000] {subprocess.py:93} INFO - [0m15:57:31    sslrootcert: None
[2024-12-11T15:57:31.196+0000] {subprocess.py:93} INFO - [0m15:57:31    application_name: dbt
[2024-12-11T15:57:31.197+0000] {subprocess.py:93} INFO - [0m15:57:31    retries: 1
[2024-12-11T15:57:31.198+0000] {subprocess.py:93} INFO - [0m15:57:31  Registered adapter: postgres=1.8.0
[2024-12-11T15:57:51.372+0000] {subprocess.py:93} INFO - [0m15:57:51    Connection test: [[31mERROR[0m]
[2024-12-11T15:57:51.372+0000] {subprocess.py:93} INFO - 
[2024-12-11T15:57:51.373+0000] {subprocess.py:93} INFO - [0m15:57:51  [31m1 check failed:[0m
[2024-12-11T15:57:51.373+0000] {subprocess.py:93} INFO - [0m15:57:51  dbt was unable to connect to the specified database.
[2024-12-11T15:57:51.374+0000] {subprocess.py:93} INFO - The database returned the following error:
[2024-12-11T15:57:51.374+0000] {subprocess.py:93} INFO - 
[2024-12-11T15:57:51.374+0000] {subprocess.py:93} INFO -   >Database Error
[2024-12-11T15:57:51.374+0000] {subprocess.py:93} INFO -   connection to server at "172.19.0.2", port 5432 failed: timeout expired
[2024-12-11T15:57:51.375+0000] {subprocess.py:93} INFO - 
[2024-12-11T15:57:51.375+0000] {subprocess.py:93} INFO - 
[2024-12-11T15:57:51.375+0000] {subprocess.py:93} INFO - Check your database credentials and try again. For more information, visit:
[2024-12-11T15:57:51.375+0000] {subprocess.py:93} INFO - https://docs.getdbt.com/docs/configure-your-profile
[2024-12-11T15:57:51.376+0000] {subprocess.py:93} INFO - 
[2024-12-11T15:57:51.376+0000] {subprocess.py:93} INFO - 
[2024-12-11T15:57:52.345+0000] {subprocess.py:97} INFO - Command exited with return code 1
[2024-12-11T15:57:52.345+0000] {taskinstance.py:441} INFO - ::group::Post task execution logs
[2024-12-11T15:57:52.358+0000] {taskinstance.py:2905} ERROR - Task failed with exception
Traceback (most recent call last):
  File "/home/airflow/.local/lib/python3.9/site-packages/airflow/models/taskinstance.py", line 465, in _execute_task
    result = _execute_callable(context=context, **execute_callable_kwargs)
  File "/home/airflow/.local/lib/python3.9/site-packages/airflow/models/taskinstance.py", line 432, in _execute_callable
    return execute_callable(context=context, **execute_callable_kwargs)
  File "/home/airflow/.local/lib/python3.9/site-packages/airflow/models/baseoperator.py", line 400, in wrapper
    return func(self, *args, **kwargs)
  File "/home/airflow/.local/lib/python3.9/site-packages/airflow/operators/bash.py", line 243, in execute
    raise AirflowException(
airflow.exceptions.AirflowException: Bash command failed. The command returned a non-zero exit code 1.
[2024-12-11T15:57:52.362+0000] {taskinstance.py:1206} INFO - Marking task as FAILED. dag_id=dbt_orchestrator, task_id=dbt_connection_check.dbt_debug, run_id=scheduled__2024-12-11T15:30:00+00:00, execution_date=20241211T153000, start_date=20241211T155728, end_date=20241211T155752
[2024-12-11T15:57:52.376+0000] {standard_task_runner.py:110} ERROR - Failed to execute job 15 for task dbt_connection_check.dbt_debug (Bash command failed. The command returned a non-zero exit code 1.; 50)
[2024-12-11T15:57:52.383+0000] {local_task_job_runner.py:240} INFO - Task exited with return code 1
[2024-12-11T15:57:52.398+0000] {taskinstance.py:3498} INFO - 0 downstream tasks scheduled from follow-on schedule check
[2024-12-11T15:57:52.400+0000] {local_task_job_runner.py:222} INFO - ::endgroup::
