[2024-12-11T15:43:10.559+0000] {local_task_job_runner.py:120} INFO - ::group::Pre task execution logs
[2024-12-11T15:43:10.589+0000] {taskinstance.py:2076} INFO - Dependencies all met for dep_context=non-requeueable deps ti=<TaskInstance: dbt_orchestrator.dbt_connection_check.dbt_debug manual__2024-12-11T15:43:09.116245+00:00 [queued]>
[2024-12-11T15:43:10.598+0000] {taskinstance.py:2076} INFO - Dependencies all met for dep_context=requeueable deps ti=<TaskInstance: dbt_orchestrator.dbt_connection_check.dbt_debug manual__2024-12-11T15:43:09.116245+00:00 [queued]>
[2024-12-11T15:43:10.599+0000] {taskinstance.py:2306} INFO - Starting attempt 1 of 1
[2024-12-11T15:43:10.611+0000] {taskinstance.py:2330} INFO - Executing <Task(BashOperator): dbt_connection_check.dbt_debug> on 2024-12-11 15:43:09.116245+00:00
[2024-12-11T15:43:10.618+0000] {standard_task_runner.py:63} INFO - Started process 50 to run task
[2024-12-11T15:43:10.621+0000] {standard_task_runner.py:90} INFO - Running: ['***', 'tasks', 'run', 'dbt_orchestrator', 'dbt_connection_check.dbt_debug', 'manual__2024-12-11T15:43:09.116245+00:00', '--job-id', '8', '--raw', '--subdir', 'DAGS_FOLDER/pipeline.py', '--cfg-path', '/tmp/tmprmgna6ud']
[2024-12-11T15:43:10.622+0000] {standard_task_runner.py:91} INFO - Job 8: Subtask dbt_connection_check.dbt_debug
[2024-12-11T15:43:10.673+0000] {task_command.py:426} INFO - Running <TaskInstance: dbt_orchestrator.dbt_connection_check.dbt_debug manual__2024-12-11T15:43:09.116245+00:00 [running]> on host e067f37bba45
[2024-12-11T15:43:10.769+0000] {taskinstance.py:2648} INFO - Exporting env vars: AIRFLOW_CTX_DAG_OWNER='Mahmoud' AIRFLOW_CTX_DAG_ID='dbt_orchestrator' AIRFLOW_CTX_TASK_ID='dbt_connection_check.dbt_debug' AIRFLOW_CTX_EXECUTION_DATE='2024-12-11T15:43:09.116245+00:00' AIRFLOW_CTX_TRY_NUMBER='1' AIRFLOW_CTX_DAG_RUN_ID='manual__2024-12-11T15:43:09.116245+00:00'
[2024-12-11T15:43:10.770+0000] {taskinstance.py:430} INFO - ::endgroup::
[2024-12-11T15:43:10.792+0000] {subprocess.py:63} INFO - Tmp dir root location: /tmp
[2024-12-11T15:43:10.792+0000] {subprocess.py:75} INFO - Running command: ['/usr/bin/bash', '-c', 'dbt debug --profiles-dir ./dbt --project-dir ./ecommerce']
[2024-12-11T15:43:10.804+0000] {subprocess.py:86} INFO - Output:
[2024-12-11T15:43:12.953+0000] {subprocess.py:93} INFO - Usage: dbt debug [OPTIONS]
[2024-12-11T15:43:12.953+0000] {subprocess.py:93} INFO - Try 'dbt debug -h' for help.
[2024-12-11T15:43:12.953+0000] {subprocess.py:93} INFO - 
[2024-12-11T15:43:12.954+0000] {subprocess.py:93} INFO - Error: Invalid value for '--project-dir': Path './ecommerce' does not exist.
[2024-12-11T15:43:13.202+0000] {subprocess.py:97} INFO - Command exited with return code 2
[2024-12-11T15:43:13.203+0000] {taskinstance.py:441} INFO - ::group::Post task execution logs
[2024-12-11T15:43:13.218+0000] {taskinstance.py:2905} ERROR - Task failed with exception
Traceback (most recent call last):
  File "/home/airflow/.local/lib/python3.9/site-packages/airflow/models/taskinstance.py", line 465, in _execute_task
    result = _execute_callable(context=context, **execute_callable_kwargs)
  File "/home/airflow/.local/lib/python3.9/site-packages/airflow/models/taskinstance.py", line 432, in _execute_callable
    return execute_callable(context=context, **execute_callable_kwargs)
  File "/home/airflow/.local/lib/python3.9/site-packages/airflow/models/baseoperator.py", line 400, in wrapper
    return func(self, *args, **kwargs)
  File "/home/airflow/.local/lib/python3.9/site-packages/airflow/operators/bash.py", line 243, in execute
    raise AirflowException(
airflow.exceptions.AirflowException: Bash command failed. The command returned a non-zero exit code 2.
[2024-12-11T15:43:13.224+0000] {taskinstance.py:1206} INFO - Marking task as FAILED. dag_id=dbt_orchestrator, task_id=dbt_connection_check.dbt_debug, run_id=manual__2024-12-11T15:43:09.116245+00:00, execution_date=20241211T154309, start_date=20241211T154310, end_date=20241211T154313
[2024-12-11T15:43:13.244+0000] {standard_task_runner.py:110} ERROR - Failed to execute job 8 for task dbt_connection_check.dbt_debug (Bash command failed. The command returned a non-zero exit code 2.; 50)
[2024-12-11T15:43:13.280+0000] {local_task_job_runner.py:240} INFO - Task exited with return code 1
[2024-12-11T15:43:13.305+0000] {taskinstance.py:3498} INFO - 0 downstream tasks scheduled from follow-on schedule check
[2024-12-11T15:43:13.307+0000] {local_task_job_runner.py:222} INFO - ::endgroup::
